Traceback (most recent call last):
  File "/home/ubuntu/anaconda2/envs/py36/lib/python3.6/http/client.py", line 566, in _readall_chunked
    value.append(self._safe_read(chunk_left))
  File "/home/ubuntu/anaconda2/envs/py36/lib/python3.6/http/client.py", line 614, in _safe_read
    raise IncompleteRead(b''.join(s), amt)
http.client.IncompleteRead: IncompleteRead(41099 bytes read, 24373 more expected)

During handling of the above exception, another exception occurred:

Traceback (most recent call last):
  File "/home/ubuntu/song_index/crawl_genie.py", line 49, in <module>
    top100List = getData(freqType,inputDateTime)
  File "/home/ubuntu/song_index/crawl_genie.py", line 29, in getData
    siteTxt = urllib.request.urlopen(reqUrl).read()
  File "/home/ubuntu/anaconda2/envs/py36/lib/python3.6/http/client.py", line 456, in read
    return self._readall_chunked()
  File "/home/ubuntu/anaconda2/envs/py36/lib/python3.6/http/client.py", line 570, in _readall_chunked
    raise IncompleteRead(b''.join(value))
http.client.IncompleteRead: IncompleteRead(220439 bytes read)
